Workbook

Sheet Metricas
C1: Metricas de la Gestión Documental - 2026
C2: Metas del tiempo | F2: PRUDENCIA | H2: Gestores | I2: Total | J2: A tiempo | K2: Fuera de tiempo | L2: Promedio
C3: A tiempo | D3: Fuera de tiempo | E3: Promedio Tiempo de respuesta | F3: Dentro del horario | G3: Fuera de horario | H3: Andersson Beltre | I3: =COUNTIF('RequestStats'!E:E,Metricas!H3) | J3: =COUNTIFS('RequestStats'!I:I, "A tiempo", 'RequestStats'!E:E,Metricas!H3) | K3: =COUNTIFS('RequestStats'!I:I, "Fuera de tiempo", 'RequestStats'!E:E,Metricas!H3) | L3: =AVERAGEIFS('RequestStats'!H:H, 'RequestStats'!C:C, ">=" & DATE(2026,1,1), 'RequestStats'!C:C, "<=" & DATE(2026,12,31), 'RequestStats'!E:E, Tabla71516911[[#This Row],[Gestores]])
C4: =COUNTIF('RequestStats'!H:H, "<02:00:01") | D4: =COUNTIF('RequestStats'!H:H, ">02:00:01") | E4: =AVERAGE('RequestStats'!H:H) | F4: =COUNTIF('RequestStats'!F:F, "Dentro del horario") | G4: =COUNTIF('RequestStats'!F:F, "Fuera de horario") | H4: Genaro Corporan B | I4: =COUNTIF('RequestStats'!E:E,Metricas!H4) | J4: =COUNTIFS('RequestStats'!I:I, "A tiempo", 'RequestStats'!E:E,Metricas!H4) | K4: =COUNTIFS('RequestStats'!I:I, "Fuera de tiempo", 'RequestStats'!E:E,Metricas!H4) | L4: =AVERAGEIFS('RequestStats'!H:H, 'RequestStats'!C:C, ">=" & DATE(2026,1,1), 'RequestStats'!C:C, "<=" & DATE(2026,12,31), 'RequestStats'!E:E, Tabla71516911[[#This Row],[Gestores]])
C5: 2026 - Stats | G5: Total: | H5: Julio Angel Thomas GarcIa | I5: =COUNTIF('RequestStats'!E:E,Metricas!H5) | J5: =COUNTIFS('RequestStats'!I:I, "A tiempo", 'RequestStats'!E:E,Metricas!H5) | K5: =COUNTIFS('RequestStats'!I:I, "Fuera de tiempo", 'RequestStats'!E:E,Metricas!H5) | L5: =AVERAGEIFS('RequestStats'!H:H, 'RequestStats'!C:C, ">=" & DATE(2026,1,1), 'RequestStats'!C:C, "<=" & DATE(2026,12,31), 'RequestStats'!E:E, Tabla71516911[[#This Row],[Gestores]])
C6: Cuenta de Solicitud | D6: Etiquetas de columna | H6: Kevin F Fernandez U | I6: =COUNTIF('RequestStats'!E:E,Metricas!H6) | J6: =COUNTIFS('RequestStats'!I:I, "A tiempo", 'RequestStats'!E:E,Metricas!H6) | K6: =COUNTIFS('RequestStats'!I:I, "Fuera de tiempo", 'RequestStats'!E:E,Metricas!H6) | L6: =AVERAGEIFS('RequestStats'!H:H, 'RequestStats'!C:C, ">=" & DATE(2026,1,1), 'RequestStats'!C:C, "<=" & DATE(2026,12,31), 'RequestStats'!E:E, Tabla71516911[[#This Row],[Gestores]])
C7: Etiquetas de fila | D7: Dentro del horario | E7: Fuera de horario | F7: Total general | G7: =(F10+F14)/2 | H7: Moises Antonio Laureano Mateo | I7: =COUNTIF('RequestStats'!E:E,Metricas!H7) | J7: =COUNTIFS('RequestStats'!I:I, "A tiempo", 'RequestStats'!E:E,Metricas!H7) | K7: =COUNTIFS('RequestStats'!I:I, "Fuera de tiempo", 'RequestStats'!E:E,Metricas!H7) | L7: =AVERAGEIFS('RequestStats'!H:H, 'RequestStats'!C:C, ">=" & DATE(2026,1,1), 'RequestStats'!C:C, "<=" & DATE(2026,12,31), 'RequestStats'!E:E, Tabla71516911[[#This Row],[Gestores]])
C8: Copia Digital | D8: =COUNTIFS('RequestStats'!B:B,"Copia Digital",'RequestStats'!F:F,"Dentro del horario") | E8: =COUNTIFS('RequestStats'!B:B,"Copia Digital",'RequestStats'!F:F,"Fuera de horario") | F8: =SUM(D8:E8) | H8: Elvis Garibal Valdez Mejia | I8: =COUNTIF('RequestStats'!E:E,Metricas!H8) | J8: =COUNTIFS('RequestStats'!I:I, "A tiempo", 'RequestStats'!E:E,Metricas!H8) | K8: =COUNTIFS('RequestStats'!I:I, "Fuera de tiempo", 'RequestStats'!E:E,Metricas!H8) | L8: =AVERAGEIFS('RequestStats'!H:H, 'RequestStats'!C:C, ">=" & DATE(2026,1,1), 'RequestStats'!C:C, "<=" & DATE(2026,12,31), 'RequestStats'!E:E, Tabla71516911[[#This Row],[Gestores]])
C9: Prestamo | D9: =COUNTIFS('RequestStats'!B:B,"Prestamo",'RequestStats'!F:F,"Dentro del horario") | E9: =COUNTIFS('RequestStats'!B:B,"Prestamo",'RequestStats'!F:F,"Fuera de horario") | F9: =SUM(D9:E9) | H9: Jose Manuel Polanco Mercedes | I9: =COUNTIF('RequestStats'!E:E,Metricas!H9) | J9: =COUNTIFS('RequestStats'!I:I, "A tiempo", 'RequestStats'!E:E,Metricas!H9) | K9: =COUNTIFS('RequestStats'!I:I, "Fuera de tiempo", 'RequestStats'!E:E,Metricas!H9) | L9: =AVERAGEIFS('RequestStats'!H:H, 'RequestStats'!C:C, ">=" & DATE(2026,1,1), 'RequestStats'!C:C, "<=" & DATE(2026,12,31), 'RequestStats'!E:E, Tabla71516911[[#This Row],[Gestores]])
C10: Total general | D10: =SUM(D8:D9) | E10: =SUM(E8:E9) | F10: =SUM(F8:F9) | H10: Federico Arsenio Lachapel | I10: =COUNTIF('RequestStats'!E:E,Metricas!H10) | J10: =COUNTIFS('RequestStats'!I:I, "A tiempo", 'RequestStats'!E:E,Metricas!H10) | K10: =COUNTIFS('RequestStats'!I:I, "Fuera de tiempo", 'RequestStats'!E:E,Metricas!H10) | L10: =AVERAGEIFS('RequestStats'!H:H, 'RequestStats'!C:C, ">=" & DATE(2026,1,1), 'RequestStats'!C:C, "<=" & DATE(2026,12,31), 'RequestStats'!E:E, Tabla71516911[[#This Row],[Gestores]])
C11: Etiquetas de fila | D11: A tiempo | E11: Fuera de tiempo | F11: Total general | H11: Julio Adolfo Merino Feliciano | I11: =COUNTIF('RequestStats'!E:E,Metricas!H11) | J11: =COUNTIFS('RequestStats'!I:I, "A tiempo", 'RequestStats'!E:E,Metricas!H11) | K11: =COUNTIFS('RequestStats'!I:I, "Fuera de tiempo", 'RequestStats'!E:E,Metricas!H11) | L11: =AVERAGEIFS('RequestStats'!H:H, 'RequestStats'!C:C, ">=" & DATE(2026,1,1), 'RequestStats'!C:C, "<=" & DATE(2026,12,31), 'RequestStats'!E:E, Tabla71516911[[#This Row],[Gestores]])
C12: Copia Digital | D12: =COUNTIFS('RequestStats'!B:B,"Copia Digital",'RequestStats'!I:I,"A tiempo") | E12: =COUNTIFS('RequestStats'!B:B,"Copia Digital",'RequestStats'!I:I,"Fuera de tiempo") | F12: =SUM(D12:E12) | H12: Jose Arturo Guzman Coste | I12: =COUNTIF('RequestStats'!E:E,Metricas!H12) | J12: =COUNTIFS('RequestStats'!I:I, "A tiempo", 'RequestStats'!E:E,Metricas!H12) | K12: =COUNTIFS('RequestStats'!I:I, "Fuera de tiempo", 'RequestStats'!E:E,Metricas!H12) | L12: =AVERAGEIFS('RequestStats'!H:H, 'RequestStats'!C:C, ">=" & DATE(2026,1,1), 'RequestStats'!C:C, "<=" & DATE(2026,12,31), 'RequestStats'!E:E, Tabla71516911[[#This Row],[Gestores]])
C13: Prestamo | D13: =COUNTIFS('RequestStats'!B:B,"Prestamo",'RequestStats'!I:I,"A tiempo") | E13: =COUNTIFS('RequestStats'!B:B,"Prestamo",'RequestStats'!I:I,"Fuera de tiempo") | F13: =SUM(D13:E13) | H13: Gestor Documental | I13: =COUNTIF('RequestStats'!E:E,Metricas!H13) | J13: =COUNTIFS('RequestStats'!I:I, "A tiempo", 'RequestStats'!E:E,Metricas!H13) | K13: =COUNTIFS('RequestStats'!I:I, "Fuera de tiempo", 'RequestStats'!E:E,Metricas!H13) | L13: =AVERAGEIFS('RequestStats'!H:H, 'RequestStats'!C:C, ">=" & DATE(2026,1,1), 'RequestStats'!C:C, "<=" & DATE(2026,12,31), 'RequestStats'!E:E, Tabla71516911[[#This Row],[Gestores]])
C14: Total general | D14: =SUM(D12:D13) | E14: =SUM(E12:E13) | F14: =SUM(F12:F13)
C61: Trimestre 1 - Stats | H61: Trimestre 1 - Stats
C63: Metas del tiempo | F63: PRUDENCIA | H63: Gestores | I63: Total | J63: A tiempo | K63: Fuera de tiempo | L63: Promedio
C64: A tiempo | D64: Fuera de tiempo | E64: Promedio Tiempo de respuesta | F64: Dentro del horario | G64: Fuera de horario | H64: Kevin F Fernandez U | I64: =COUNTIFS('RequestStats'!E:E,Tabla792627[[#This Row],[Gestores]], 'RequestStats'!C:C, ">=" & DATE(2026,1,1), 'RequestStats'!C:C, "<=" & DATE(2026,4,1)) | J64: =COUNTIFS('RequestStats'!I:I, "A tiempo", 'RequestStats'!E:E,Metricas!H64, 'RequestStats'!C:C, ">=" & DATE(2026,1,1), 'RequestStats'!C:C, "<=" & DATE(2026,4,1)) | K64: =COUNTIFS('RequestStats'!I:I, "Fuera de tiempo", 'RequestStats'!E:E,Metricas!H64, 'RequestStats'!C:C, ">=" & DATE(2026,1,1), 'RequestStats'!C:C, "<=" & DATE(2026,4,1)) | L64: =AVERAGEIFS('RequestStats'!H:H, 'RequestStats'!C:C, ">=" & DATE(2026,1,1), 'RequestStats'!C:C, "<=" & DATE(2026,4,1), 'RequestStats'!E:E, Tabla792627[[#This Row],[Gestores]])
C65: =COUNTIFS('RequestStats'!H:H, "<=02:00:00", 'RequestStats'!C:C, ">=" & DATE(2026,1,1), 'RequestStats'!C:C, "<=" & DATE(2026,4,1)) | D65: =COUNTIFS('RequestStats'!H:H, ">02:00:01", 'RequestStats'!C:C, ">=" & DATE(2026,1,1), 'RequestStats'!C:C, "<=" & DATE(2026,4,1)) | E65: =AVERAGEIFS('RequestStats'!H:H,'RequestStats'!C:C, "<=" & DATE(2026,4,1), 'RequestStats'!C:C, ">=" & DATE(2026,1,1)) | F65: =COUNTIFS('RequestStats'!C:C, ">=" & DATE(2026,1,1), 'RequestStats'!C:C, "<=" & DATE(2026,4,1), 'RequestStats'!F:F, "Dentro del Horario") | G65: =COUNTIFS('RequestStats'!C:C, ">=" & DATE(2026,1,1), 'RequestStats'!C:C, "<=" & DATE(2026,4,1), 'RequestStats'!F:F, "Fuera de Horario") | H65: Moises Antonio Laureano Mateo | I65: =COUNTIFS('RequestStats'!E:E,Tabla792627[[#This Row],[Gestores]], 'RequestStats'!C:C, ">=" & DATE(2026,1,1), 'RequestStats'!C:C, "<=" & DATE(2026,4,1)) | J65: =COUNTIFS('RequestStats'!I:I, "A tiempo", 'RequestStats'!E:E,Metricas!H65, 'RequestStats'!C:C, ">=" & DATE(2026,1,1), 'RequestStats'!C:C, "<=" & DATE(2026,4,1)) | K65: =COUNTIFS('RequestStats'!I:I, "Fuera de tiempo", 'RequestStats'!E:E,Metricas!H65, 'RequestStats'!C:C, ">=" & DATE(2026,1,1), 'RequestStats'!C:C, "<=" & DATE(2026,4,1)) | L65: =AVERAGEIFS('RequestStats'!H:H, 'RequestStats'!C:C, ">=" & DATE(2026,1,1), 'RequestStats'!C:C, "<=" & DATE(2026,4,1), 'RequestStats'!E:E, Tabla792627[[#This Row],[Gestores]])
C66: Trimestre 1 - Stats | D66: Enero - Marzo | E66: Año | F66: 2026 | G66: Total: | H66: Andersson Beltre | I66: =COUNTIFS('RequestStats'!E:E,Tabla792627[[#This Row],[Gestores]], 'RequestStats'!C:C, ">=" & DATE(2026,1,1), 'RequestStats'!C:C, "<=" & DATE(2026,4,1)) | J66: =COUNTIFS('RequestStats'!I:I, "A tiempo", 'RequestStats'!E:E,Metricas!H66, 'RequestStats'!C:C, ">=" & DATE(2026,1,1), 'RequestStats'!C:C, "<=" & DATE(2026,4,1)) | K66: =COUNTIFS('RequestStats'!I:I, "Fuera de tiempo", 'RequestStats'!E:E,Metricas!H66, 'RequestStats'!C:C, ">=" & DATE(2026,1,1), 'RequestStats'!C:C, "<=" & DATE(2026,4,1)) | L66: =AVERAGEIFS('RequestStats'!H:H, 'RequestStats'!C:C, ">=" & DATE(2026,1,1), 'RequestStats'!C:C, "<=" & DATE(2026,4,1), 'RequestStats'!E:E, Tabla792627[[#This Row],[Gestores]])
C67: Cuenta de Solicitud | D67: Etiquetas de columna | H67: Julio Angel Thomas GarcIa | I67: =COUNTIFS('RequestStats'!E:E,Tabla792627[[#This Row],[Gestores]], 'RequestStats'!C:C, ">=" & DATE(2026,1,1), 'RequestStats'!C:C, "<=" & DATE(2026,4,1)) | J67: =COUNTIFS('RequestStats'!I:I, "A tiempo", 'RequestStats'!E:E,Metricas!H67, 'RequestStats'!C:C, ">=" & DATE(2026,1,1), 'RequestStats'!C:C, "<=" & DATE(2026,4,1)) | K67: =COUNTIFS('RequestStats'!I:I, "Fuera de tiempo", 'RequestStats'!E:E,Metricas!H67, 'RequestStats'!C:C, ">=" & DATE(2026,1,1), 'RequestStats'!C:C, "<=" & DATE(2026,4,1)) | L67: =AVERAGEIFS('RequestStats'!H:H, 'RequestStats'!C:C, ">=" & DATE(2026,1,1), 'RequestStats'!C:C, "<=" & DATE(2026,4,1), 'RequestStats'!E:E, Tabla792627[[#This Row],[Gestores]])
C68: Etiquetas de fila | D68: Dentro del horario | E68: Fuera de horario | F68: Total general | G68: =(F71+F75)/2 | H68: Genaro Corporan B | I68: =COUNTIFS('RequestStats'!E:E,Tabla792627[[#This Row],[Gestores]], 'RequestStats'!C:C, ">=" & DATE(2026,1,1), 'RequestStats'!C:C, "<=" & DATE(2026,4,1)) | J68: =COUNTIFS('RequestStats'!I:I, "A tiempo", 'RequestStats'!E:E,Metricas!H68, 'RequestStats'!C:C, ">=" & DATE(2026,1,1), 'RequestStats'!C:C, "<=" & DATE(2026,4,1)) | K68: =COUNTIFS('RequestStats'!I:I, "Fuera de tiempo", 'RequestStats'!E:E,Metricas!H68, 'RequestStats'!C:C, ">=" & DATE(2026,1,1), 'RequestStats'!C:C, "<=" & DATE(2026,4,1)) | L68: =AVERAGEIFS('RequestStats'!H:H, 'RequestStats'!C:C, ">=" & DATE(2026,1,1), 'RequestStats'!C:C, "<=" & DATE(2026,4,1), 'RequestStats'!E:E, Tabla792627[[#This Row],[Gestores]])
C69: Copia Digital | D69: =COUNTIFS('RequestStats'!C:C, ">=" & DATE(2026,1,1), 'RequestStats'!C:C, "<=" & DATE(2026,4,1), 'RequestStats'!F:F, "Dentro del Horario", 'RequestStats'!B:B, "Copia Digital" ) | E69: =COUNTIFS('RequestStats'!C:C, ">=" & DATE(2026,1,1), 'RequestStats'!C:C, "<=" & DATE(2026,4,1), 'RequestStats'!F:F, "Fuera de Horario", 'RequestStats'!B:B, "Copia Digital" ) | F69: =SUM(D69:E69) | H69: Federico Arsenio Lachapel | I69: =COUNTIFS('RequestStats'!E:E,Tabla792627[[#This Row],[Gestores]], 'RequestStats'!C:C, ">=" & DATE(2026,1,1), 'RequestStats'!C:C, "<=" & DATE(2026,4,1)) | J69: =COUNTIFS('RequestStats'!I:I, "A tiempo", 'RequestStats'!E:E,Metricas!H69, 'RequestStats'!C:C, ">=" & DATE(2026,1,1), 'RequestStats'!C:C, "<=" & DATE(2026,4,1)) | K69: =COUNTIFS('RequestStats'!I:I, "Fuera de tiempo", 'RequestStats'!E:E,Metricas!H69, 'RequestStats'!C:C, ">=" & DATE(2026,1,1), 'RequestStats'!C:C, "<=" & DATE(2026,4,1)) | L69: =AVERAGEIFS('RequestStats'!H:H, 'RequestStats'!C:C, ">=" & DATE(2026,1,1), 'RequestStats'!C:C, "<=" & DATE(2026,4,1), 'RequestStats'!E:E, Tabla792627[[#This Row],[Gestores]])
C70: Prestamo | D70: =COUNTIFS('RequestStats'!C:C, ">=" & DATE(2026,1,1), 'RequestStats'!C:C, "<=" & DATE(2026,4,1), 'RequestStats'!F:F, "Dentro del Horario", 'RequestStats'!B:B, "Prestamo" ) | E70: =COUNTIFS('RequestStats'!C:C, ">=" & DATE(2026,1,1), 'RequestStats'!C:C, "<=" & DATE(2026,4,1), 'RequestStats'!F:F, "Fuera de Horario", 'RequestStats'!B:B, "Prestamo" ) | F70: =SUM(D70:E70) | H70: Elvis Garibal Valdez Mejia | I70: =COUNTIFS('RequestStats'!E:E,Tabla792627[[#This Row],[Gestores]], 'RequestStats'!C:C, ">=" & DATE(2026,1,1), 'RequestStats'!C:C, "<=" & DATE(2026,4,1)) | J70: =COUNTIFS('RequestStats'!I:I, "A tiempo", 'RequestStats'!E:E,Metricas!H70, 'RequestStats'!C:C, ">=" & DATE(2026,1,1), 'RequestStats'!C:C, "<=" & DATE(2026,4,1)) | K70: =COUNTIFS('RequestStats'!I:I, "Fuera de tiempo", 'RequestStats'!E:E,Metricas!H70, 'RequestStats'!C:C, ">=" & DATE(2026,1,1), 'RequestStats'!C:C, "<=" & DATE(2026,4,1)) | L70: =AVERAGEIFS('RequestStats'!H:H, 'RequestStats'!C:C, ">=" & DATE(2026,1,1), 'RequestStats'!C:C, "<=" & DATE(2026,4,1), 'RequestStats'!E:E, Tabla792627[[#This Row],[Gestores]])
C71: Total general | D71: =SUM(D69:D70) | E71: =SUM(E69:E70) | F71: =SUM(F69:F70) | H71: Jose Manuel Polanco Mercedes | I71: =COUNTIFS('RequestStats'!E:E,Tabla792627[[#This Row],[Gestores]], 'RequestStats'!C:C, ">=" & DATE(2026,1,1), 'RequestStats'!C:C, "<=" & DATE(2026,4,1)) | J71: =COUNTIFS('RequestStats'!I:I, "A tiempo", 'RequestStats'!E:E,Metricas!H71, 'RequestStats'!C:C, ">=" & DATE(2026,1,1), 'RequestStats'!C:C, "<=" & DATE(2026,4,1)) | K71: =COUNTIFS('RequestStats'!I:I, "Fuera de tiempo", 'RequestStats'!E:E,Metricas!H71, 'RequestStats'!C:C, ">=" & DATE(2026,1,1), 'RequestStats'!C:C, "<=" & DATE(2026,4,1)) | L71: =AVERAGEIFS('RequestStats'!H:H, 'RequestStats'!C:C, ">=" & DATE(2026,1,1), 'RequestStats'!C:C, "<=" & DATE(2026,4,1), 'RequestStats'!E:E, Tabla792627[[#This Row],[Gestores]])
C72: Etiquetas de fila | D72: A tiempo | E72: Fuera de tiempo | F72: Total general | H72: Francisco Sanchez V | I72: =COUNTIFS('RequestStats'!E:E,Tabla792627[[#This Row],[Gestores]], 'RequestStats'!C:C, ">=" & DATE(2026,1,1), 'RequestStats'!C:C, "<=" & DATE(2026,4,1)) | J72: =COUNTIFS('RequestStats'!I:I, "A tiempo", 'RequestStats'!E:E,Metricas!H72, 'RequestStats'!C:C, ">=" & DATE(2026,1,1), 'RequestStats'!C:C, "<=" & DATE(2026,4,1)) | K72: =COUNTIFS('RequestStats'!I:I, "Fuera de tiempo", 'RequestStats'!E:E,Metricas!H72, 'RequestStats'!C:C, ">=" & DATE(2026,1,1), 'RequestStats'!C:C, "<=" & DATE(2026,4,1)) | L72: =AVERAGEIFS('RequestStats'!H:H, 'RequestStats'!C:C, ">=" & DATE(2026,1,1), 'RequestStats'!C:C, "<=" & DATE(2026,4,1), 'RequestStats'!E:E, Tabla792627[[#This Row],[Gestores]])
C73: Copia Digital | D73: =COUNTIFS('RequestStats'!C:C, ">=" & DATE(2026,1,1), 'RequestStats'!C:C, "<=" & DATE(2026,4,1),'RequestStats'!B:B,"Copia Digital",'RequestStats'!I:I,"A tiempo") | E73: =COUNTIFS('RequestStats'!C:C, ">=" & DATE(2026,1,1), 'RequestStats'!C:C, "<=" & DATE(2026,4,1),'RequestStats'!B:B,"Copia Digital",'RequestStats'!I:I,"Fuera de tiempo") | F73: =SUM(D73:E73) | H73: Gestor Documental | I73: =COUNTIFS('RequestStats'!E:E,Tabla792627[[#This Row],[Gestores]], 'RequestStats'!C:C, ">=" & DATE(2026,1,1), 'RequestStats'!C:C, "<=" & DATE(2026,4,1)) | J73: =COUNTIFS('RequestStats'!I:I, "A tiempo", 'RequestStats'!E:E,Metricas!H73, 'RequestStats'!C:C, ">=" & DATE(2026,1,1), 'RequestStats'!C:C, "<=" & DATE(2026,4,1)) | K73: =COUNTIFS('RequestStats'!I:I, "Fuera de tiempo", 'RequestStats'!E:E,Metricas!H73, 'RequestStats'!C:C, ">=" & DATE(2026,1,1), 'RequestStats'!C:C, "<=" & DATE(2026,4,1)) | L73: =AVERAGEIFS('RequestStats'!H:H, 'RequestStats'!C:C, ">=" & DATE(2026,1,1), 'RequestStats'!C:C, "<=" & DATE(2026,4,1), 'RequestStats'!E:E, Tabla792627[[#This Row],[Gestores]])
C74: Prestamo | D74: =COUNTIFS('RequestStats'!C:C, ">=" & DATE(2026,1,1), 'RequestStats'!C:C, "<=" & DATE(2026,4,1),'RequestStats'!B:B,"Prestamo",'RequestStats'!I:I,"A tiempo") | E74: =COUNTIFS('RequestStats'!C:C, ">=" & DATE(2026,1,1), 'RequestStats'!C:C, "<=" & DATE(2026,4,1),'RequestStats'!B:B,"Prestamo",'RequestStats'!I:I,"Fuera de tiempo") | F74: =SUM(D74:E74)
C75: Total general | D75: =SUM(D73:D74) | E75: =SUM(E73:E74) | F75: =SUM(F73:F74)
C122: Trimestre 2 - Stats | H122: Trimestre 2 - Stats
C124: Metas del tiempo | F124: PRUDENCIA | H124: Gestores | I124: Total | J124: A tiempo | K124: Fuera de tiempo | L124: Promedio
C125: A tiempo | D125: Fuera de tiempo | E125: Promedio Tiempo de respuesta | F125: Dentro del horario | G125: Fuera de horario | H125: Andersson Beltre | I125: =COUNTIFS('RequestStats'!E:E,Tabla79262713[[#This Row],[Gestores]], 'RequestStats'!C:C, ">=" & DATE(2026,4,1), 'RequestStats'!C:C, "<=" & DATE(2026,7,1)) | J125: =COUNTIFS('RequestStats'!I:I, "A tiempo", 'RequestStats'!E:E,Metricas!H125, 'RequestStats'!C:C, ">=" & DATE(2026,4,1), 'RequestStats'!C:C, "<=" & DATE(2026,7,1)) | K125: =COUNTIFS('RequestStats'!I:I, "Fuera de tiempo", 'RequestStats'!E:E,Metricas!H125, 'RequestStats'!C:C, ">=" & DATE(2026,4,1), 'RequestStats'!C:C, "<=" & DATE(2026,7,1)) | L125: =AVERAGEIFS('RequestStats'!H:H, 'RequestStats'!C:C, ">=" & DATE(2026,4,1), 'RequestStats'!C:C, "<=" & DATE(2026,7,1), 'RequestStats'!E:E, Tabla79262713[[#This Row],[Gestores]])
C126: =COUNTIFS('RequestStats'!H:H, "<=02:00:00", 'RequestStats'!C:C, ">=" & DATE(2026,4,1), 'RequestStats'!C:C, "<=" & DATE(2026,7,1)) | D126: =COUNTIFS('RequestStats'!H:H, ">02:00:01", 'RequestStats'!C:C, ">=" & DATE(2026,4,1), 'RequestStats'!C:C, "<=" & DATE(2026,7,1)) | E126: =AVERAGEIFS('RequestStats'!H:H,'RequestStats'!C:C, "<=" & DATE(2026,7,1), 'RequestStats'!C:C, ">=" & DATE(2026,4,1)) | F126: =COUNTIFS('RequestStats'!C:C, ">=" & DATE(2026,4,1), 'RequestStats'!C:C, "<=" & DATE(2026,7,1), 'RequestStats'!F:F, "Dentro del Horario") | G126: =COUNTIFS('RequestStats'!C:C, ">=" & DATE(2026,4,1), 'RequestStats'!C:C, "<=" & DATE(2026,7,1), 'RequestStats'!F:F, "Fuera de Horario") | H126: Federico Arsenio Lachapel | I126: =COUNTIFS('RequestStats'!E:E,Tabla79262713[[#This Row],[Gestores]], 'RequestStats'!C:C, ">=" & DATE(2026,4,1), 'RequestStats'!C:C, "<=" & DATE(2026,7,1)) | J126: =COUNTIFS('RequestStats'!I:I, "A tiempo", 'RequestStats'!E:E,Metricas!H126, 'RequestStats'!C:C, ">=" & DATE(2026,4,1), 'RequestStats'!C:C, "<=" & DATE(2026,7,1)) | K126: =COUNTIFS('RequestStats'!I:I, "Fuera de tiempo", 'RequestStats'!E:E,Metricas!H126, 'RequestStats'!C:C, ">=" & DATE(2026,4,1), 'RequestStats'!C:C, "<=" & DATE(2026,7,1)) | L126: =AVERAGEIFS('RequestStats'!H:H, 'RequestStats'!C:C, ">=" & DATE(2026,4,1), 'RequestStats'!C:C, "<=" & DATE(2026,7,1), 'RequestStats'!E:E, Tabla79262713[[#This Row],[Gestores]])
C127: Trimestre 2 - Stats | D127: Abril - Junio | E127: Año | F127: 2026 | G127: Total: | H127: Julio Angel Thomas GarcIa | I127: =COUNTIFS('RequestStats'!E:E,Tabla79262713[[#This Row],[Gestores]], 'RequestStats'!C:C, ">=" & DATE(2026,4,1), 'RequestStats'!C:C, "<=" & DATE(2026,7,1)) | J127: =COUNTIFS('RequestStats'!I:I, "A tiempo", 'RequestStats'!E:E,Metricas!H127, 'RequestStats'!C:C, ">=" & DATE(2026,4,1), 'RequestStats'!C:C, "<=" & DATE(2026,7,1)) | K127: =COUNTIFS('RequestStats'!I:I, "Fuera de tiempo", 'RequestStats'!E:E,Metricas!H127, 'RequestStats'!C:C, ">=" & DATE(2026,4,1), 'RequestStats'!C:C, "<=" & DATE(2026,7,1)) | L127: =AVERAGEIFS('RequestStats'!H:H, 'RequestStats'!C:C, ">=" & DATE(2026,4,1), 'RequestStats'!C:C, "<=" & DATE(2026,7,1), 'RequestStats'!E:E, Tabla79262713[[#This Row],[Gestores]])
C128: Cuenta de Solicitud | D128: Etiquetas de columna | H128: Jose Manuel Polanco Mercedes | I128: =COUNTIFS('RequestStats'!E:E,Tabla79262713[[#This Row],[Gestores]], 'RequestStats'!C:C, ">=" & DATE(2026,4,1), 'RequestStats'!C:C, "<=" & DATE(2026,7,1)) | J128: =COUNTIFS('RequestStats'!I:I, "A tiempo", 'RequestStats'!E:E,Metricas!H128, 'RequestStats'!C:C, ">=" & DATE(2026,4,1), 'RequestStats'!C:C, "<=" & DATE(2026,7,1)) | K128: =COUNTIFS('RequestStats'!I:I, "Fuera de tiempo", 'RequestStats'!E:E,Metricas!H128, 'RequestStats'!C:C, ">=" & DATE(2026,4,1), 'RequestStats'!C:C, "<=" & DATE(2026,7,1)) | L128: =AVERAGEIFS('RequestStats'!H:H, 'RequestStats'!C:C, ">=" & DATE(2026,4,1), 'RequestStats'!C:C, "<=" & DATE(2026,7,1), 'RequestStats'!E:E, Tabla79262713[[#This Row],[Gestores]])
C129: Etiquetas de fila | D129: Dentro del horario | E129: Fuera de horario | F129: Total general | G129: =(F132+F136)/2 | H129: Moises Antonio Laureano Mateo | I129: =COUNTIFS('RequestStats'!E:E,Tabla79262713[[#This Row],[Gestores]], 'RequestStats'!C:C, ">=" & DATE(2026,4,1), 'RequestStats'!C:C, "<=" & DATE(2026,7,1)) | J129: =COUNTIFS('RequestStats'!I:I, "A tiempo", 'RequestStats'!E:E,Metricas!H129, 'RequestStats'!C:C, ">=" & DATE(2026,4,1), 'RequestStats'!C:C, "<=" & DATE(2026,7,1)) | K129: =COUNTIFS('RequestStats'!I:I, "Fuera de tiempo", 'RequestStats'!E:E,Metricas!H129, 'RequestStats'!C:C, ">=" & DATE(2026,4,1), 'RequestStats'!C:C, "<=" & DATE(2026,7,1)) | L129: =AVERAGEIFS('RequestStats'!H:H, 'RequestStats'!C:C, ">=" & DATE(2026,4,1), 'RequestStats'!C:C, "<=" & DATE(2026,7,1), 'RequestStats'!E:E, Tabla79262713[[#This Row],[Gestores]])
C130: Copia Digital | D130: =COUNTIFS('RequestStats'!C:C, ">=" & DATE(2026,4,1), 'RequestStats'!C:C, "<=" & DATE(2026,7,1), 'RequestStats'!F:F, "Dentro del Horario", 'RequestStats'!B:B, "Copia Digital" ) | E130: =COUNTIFS('RequestStats'!C:C, ">=" & DATE(2026,4,1), 'RequestStats'!C:C, "<=" & DATE(2026,7,1), 'RequestStats'!F:F, "Fuera de Horario", 'RequestStats'!B:B, "Copia Digital" ) | F130: =SUM(D130:E130) | H130: Elvis Garibal Valdez Mejia | I130: =COUNTIFS('RequestStats'!E:E,Tabla79262713[[#This Row],[Gestores]], 'RequestStats'!C:C, ">=" & DATE(2026,4,1), 'RequestStats'!C:C, "<=" & DATE(2026,7,1)) | J130: =COUNTIFS('RequestStats'!I:I, "A tiempo", 'RequestStats'!E:E,Metricas!H130, 'RequestStats'!C:C, ">=" & DATE(2026,4,1), 'RequestStats'!C:C, "<=" & DATE(2026,7,1)) | K130: =COUNTIFS('RequestStats'!I:I, "Fuera de tiempo", 'RequestStats'!E:E,Metricas!H130, 'RequestStats'!C:C, ">=" & DATE(2026,4,1), 'RequestStats'!C:C, "<=" & DATE(2026,7,1)) | L130: =AVERAGEIFS('RequestStats'!H:H, 'RequestStats'!C:C, ">=" & DATE(2026,4,1), 'RequestStats'!C:C, "<=" & DATE(2026,7,1), 'RequestStats'!E:E, Tabla79262713[[#This Row],[Gestores]])
C131: Prestamo | D131: =COUNTIFS('RequestStats'!C:C, ">=" & DATE(2026,4,1), 'RequestStats'!C:C, "<=" & DATE(2026,7,1), 'RequestStats'!F:F, "Dentro del Horario", 'RequestStats'!B:B, "Prestamo" ) | E131: =COUNTIFS('RequestStats'!C:C, ">=" & DATE(2026,4,1), 'RequestStats'!C:C, "<=" & DATE(2026,7,1), 'RequestStats'!F:F, "Fuera de Horario", 'RequestStats'!B:B, "Prestamo" ) | F131: =SUM(D131:E131) | H131: Jose Arturo Guzman Coste | I131: =COUNTIFS('RequestStats'!E:E,Tabla79262713[[#This Row],[Gestores]], 'RequestStats'!C:C, ">=" & DATE(2026,4,1), 'RequestStats'!C:C, "<=" & DATE(2026,7,1)) | J131: =COUNTIFS('RequestStats'!I:I, "A tiempo", 'RequestStats'!E:E,Metricas!H131, 'RequestStats'!C:C, ">=" & DATE(2026,4,1), 'RequestStats'!C:C, "<=" & DATE(2026,7,1)) | K131: =COUNTIFS('RequestStats'!I:I, "Fuera de tiempo", 'RequestStats'!E:E,Metricas!H131, 'RequestStats'!C:C, ">=" & DATE(2026,4,1), 'RequestStats'!C:C, "<=" & DATE(2026,7,1)) | L131: =AVERAGEIFS('RequestStats'!H:H, 'RequestStats'!C:C, ">=" & DATE(2026,4,1), 'RequestStats'!C:C, "<=" & DATE(2026,7,1), 'RequestStats'!E:E, Tabla79262713[[#This Row],[Gestores]])
C132: Total general | D132: =SUM(D130:D131) | E132: =SUM(E130:E131) | F132: =SUM(F130:F131) | H132: Julio Adolfo Merino Feliciano | I132: =COUNTIFS('RequestStats'!E:E,Tabla79262713[[#This Row],[Gestores]], 'RequestStats'!C:C, ">=" & DATE(2026,4,1), 'RequestStats'!C:C, "<=" & DATE(2026,7,1)) | J132: =COUNTIFS('RequestStats'!I:I, "A tiempo", 'RequestStats'!E:E,Metricas!H132, 'RequestStats'!C:C, ">=" & DATE(2026,4,1), 'RequestStats'!C:C, "<=" & DATE(2026,7,1)) | K132: =COUNTIFS('RequestStats'!I:I, "Fuera de tiempo", 'RequestStats'!E:E,Metricas!H132, 'RequestStats'!C:C, ">=" & DATE(2026,4,1), 'RequestStats'!C:C, "<=" & DATE(2026,7,1)) | L132: =AVERAGEIFS('RequestStats'!H:H, 'RequestStats'!C:C, ">=" & DATE(2026,4,1), 'RequestStats'!C:C, "<=" & DATE(2026,7,1), 'RequestStats'!E:E, Tabla79262713[[#This Row],[Gestores]])
C133: Etiquetas de fila | D133: A tiempo | E133: Fuera de tiempo | F133: Total general | H133: Genaro Corporan B | I133: =COUNTIFS('RequestStats'!E:E,Tabla79262713[[#This Row],[Gestores]], 'RequestStats'!C:C, ">=" & DATE(2026,4,1), 'RequestStats'!C:C, "<=" & DATE(2026,7,1)) | J133: =COUNTIFS('RequestStats'!I:I, "A tiempo", 'RequestStats'!E:E,Metricas!H133, 'RequestStats'!C:C, ">=" & DATE(2026,4,1), 'RequestStats'!C:C, "<=" & DATE(2026,7,1)) | K133: =COUNTIFS('RequestStats'!I:I, "Fuera de tiempo", 'RequestStats'!E:E,Metricas!H133, 'RequestStats'!C:C, ">=" & DATE(2026,4,1), 'RequestStats'!C:C, "<=" & DATE(2026,7,1)) | L133: =AVERAGEIFS('RequestStats'!H:H, 'RequestStats'!C:C, ">=" & DATE(2026,4,1), 'RequestStats'!C:C, "<=" & DATE(2026,7,1), 'RequestStats'!E:E, Tabla79262713[[#This Row],[Gestores]])
C134: Copia Digital | D134: =COUNTIFS('RequestStats'!C:C, ">=" & DATE(2026,4,1), 'RequestStats'!C:C, "<=" & DATE(2026,7,1),'RequestStats'!B:B,"Copia Digital",'RequestStats'!I:I,"A tiempo") | E134: =COUNTIFS('RequestStats'!C:C, ">=" & DATE(2026,4,1), 'RequestStats'!C:C, "<=" & DATE(2026,7,1),'RequestStats'!B:B,"Copia Digital",'RequestStats'!I:I,"Fuera de tiempo") | F134: =SUM(D134:E134) | H134: Gestor Documental | I134: =COUNTIFS('RequestStats'!E:E,Tabla79262713[[#This Row],[Gestores]], 'RequestStats'!C:C, ">=" & DATE(2026,4,1), 'RequestStats'!C:C, "<=" & DATE(2026,7,1)) | J134: =COUNTIFS('RequestStats'!I:I, "A tiempo", 'RequestStats'!E:E,Metricas!H134, 'RequestStats'!C:C, ">=" & DATE(2026,4,1), 'RequestStats'!C:C, "<=" & DATE(2026,7,1)) | K134: =COUNTIFS('RequestStats'!I:I, "Fuera de tiempo", 'RequestStats'!E:E,Metricas!H134, 'RequestStats'!C:C, ">=" & DATE(2026,4,1), 'RequestStats'!C:C, "<=" & DATE(2026,7,1)) | L134: =AVERAGEIFS('RequestStats'!H:H, 'RequestStats'!C:C, ">=" & DATE(2026,4,1), 'RequestStats'!C:C, "<=" & DATE(2026,7,1), 'RequestStats'!E:E, Tabla79262713[[#This Row],[Gestores]])
...

Sheet RequestStats
A1: ID | B1: Solicitud | C1: Creación | D1: Respuesta | E1: Gestor | F1: Prudencia | G1: ValidaciónCreación | H1: TiempoLaboralEfectivo | I1: Calificación | J1: Trimestre
L2: {=_xlfn.UNIQUE(E:E)}
L3: Andersson Beltre | O3: Andersson Beltre
L4: Genaro Corporan B | O4: Genaro Corporan B
L5: Julio Angel Thomas GarcIa | O5: Julio Angel Thomas GarcIa
L6: Kevin F Fernandez U | O6: Kevin F Fernandez U
L7: Moises Antonio Laureano Mateo | O7: Moises Antonio Laureano Mateo
L8: Elvis Garibal Valdez Mejia | O8: Elvis G Valdez M
L9: Jose Manuel Polanco Mercedes | O9: Federico Arsenio L
L10: Federico Arsenio Lachapel | O10: Julio Adolfo Merino Feliciano
L11: Julio Adolfo Merino Feliciano | O11: Jose Manuel Polanco Mercedes
L12: Jose Arturo Guzman Coste | O12: Jose Arturo Guzman Coste
L13: Juan Francisco Silvestre Ramirez
L14: Gestor Documental
L15: Francisco Sanchez Vasquez
L16: 0

Sheet Interacciones con el portal
A1: ID | B1: Solicitud | C1: Creación | D1: Respuesta | E1: Gestor | F1: Estado | G1: Condición | H1: Situación solicitud

Sheet Prestamo
A1: ID | B1: Creado por | C1: Creado | D1: Area | E1: Solicitud | F1: Tipo de Documento | G1: Cantidad de Documentos | H1: Cantidad de cajas | I1: Comentarios | J1: Estado | K1: Situación Solicitud | L1: Condición Aprobación | M1: Copiar a: | N1: Título

Sheet Copia Digital
A1: ID | B1: Creado por | C1: Creado | D1: Area | E1: Solicitud | F1: RNC o Cédula | G1: Razón Social o Nombre comercial | H1: Tipo de Documento | I1: Área de origen del documento | J1: Fecha del documento | K1: Cantidad de Documentos | L1: Motivo de la solicitud | M1: Copiar a: | N1: Documento solicitado

Sheet SolicitudesLaFeria
A1: ID | B1: Creado | C1: RNC / Cédula | D1: Nombre o Razón Social | E1: Tipo de Contribuyente | F1: Asunto / Trámite | G1: Fecha del documento | H1: Fecha de recepción | I1: Tipo de Solicitud | J1: Solicitante | K1: Estado | L1: Condición | M1: Modificado | N1: Modificado por

Sheet InteraccionesLaFeria
A1: ID | B1: Creado | C1: RNC / Cédula | D1: Nombre o Razón Social | E1: Tipo de Contribuyente | F1: Asunto / Trámite | G1: Fecha del documento | H1: Fecha de recepción | I1: Tipo de Solicitud | J1: Solicitante | K1: Estado | L1: Condición | M1: Modificado | N1: Modificado por

Sheet Digitalización en AG
A1: Automatizada
A2: NO | B2: ARCHIVO DE GESTIÓN | C2: DIGITALIZACIÓN DE DOCUMENTOS

Sheet Metricas 2025
C1: Metas del tiempo | F1: PRUDENCIA
C2: A tiempo | D2: Fuera de tiempo | E2: Promedio Tiempo de respuesta | F2: Dentro del horario | G2: Fuera de horario
C3: =COUNTIF('RequestStats'!H:H, "<00:59:59") | D3: =COUNTIF('RequestStats'!H:H, ">00:59:59") | E3: =AVERAGE('RequestStats 2025'!H:H) | F3: =COUNTIF('RequestStats'!F:F, "Dentro del horario") | G3: =COUNTIF('RequestStats'!F:F, "Fuera de horario")
H5: Gestores | I5: Total | J5: A tiempo | K5: Fuera de tiempo | L5: Promedio
H6: Kevin F Fernandez U | I6: =COUNTIF('RequestStats'!D:D,'Metricas 2025'!H6) | J6: =COUNTIFS('RequestStats'!H:H, "A tiempo", 'RequestStats'!D:D,'Metricas 2025'!H6) | K6: =COUNTIFS('RequestStats'!H:H, "Fuera de tiempo", 'RequestStats'!D:D,'Metricas 2025'!H6) | L6: =AVERAGEIFS('RequestStats'!G:G, 'RequestStats'!B:B, ">=" & DATE(2025,1,1), 'RequestStats'!B:B, "<=" & DATE(2025,12,31), 'RequestStats'!D:D, Tabla7151625[[#This Row],[Gestores]])
H7: Moises A Laureano M | I7: =COUNTIF('RequestStats'!D:D,'Metricas 2025'!H7) | J7: =COUNTIFS('RequestStats'!H:H, "A tiempo", 'RequestStats'!D:D,'Metricas 2025'!H7) | K7: =COUNTIFS('RequestStats'!H:H, "Fuera de tiempo", 'RequestStats'!D:D,'Metricas 2025'!H7) | L7: =AVERAGEIFS('RequestStats'!G:G, 'RequestStats'!B:B, ">=" & DATE(2025,1,1), 'RequestStats'!B:B, "<=" & DATE(2025,12,31), 'RequestStats'!D:D, Tabla7151625[[#This Row],[Gestores]])
H8: Andersson Beltre | I8: =COUNTIF('RequestStats'!D:D,'Metricas 2025'!H8) | J8: =COUNTIFS('RequestStats'!H:H, "A tiempo", 'RequestStats'!D:D,'Metricas 2025'!H8) | K8: =COUNTIFS('RequestStats'!H:H, "Fuera de tiempo", 'RequestStats'!D:D,'Metricas 2025'!H8) | L8: =AVERAGEIFS('RequestStats'!G:G, 'RequestStats'!B:B, ">=" & DATE(2025,1,1), 'RequestStats'!B:B, "<=" & DATE(2025,12,31), 'RequestStats'!D:D, Tabla7151625[[#This Row],[Gestores]])
H9: Julio A Thomas G | I9: =COUNTIF('RequestStats'!D:D,'Metricas 2025'!H9) | J9: =COUNTIFS('RequestStats'!H:H, "A tiempo", 'RequestStats'!D:D,'Metricas 2025'!H9) | K9: =COUNTIFS('RequestStats'!H:H, "Fuera de tiempo", 'RequestStats'!D:D,'Metricas 2025'!H9) | L9: =AVERAGEIFS('RequestStats'!G:G, 'RequestStats'!B:B, ">=" & DATE(2025,1,1), 'RequestStats'!B:B, "<=" & DATE(2025,12,31), 'RequestStats'!D:D, Tabla7151625[[#This Row],[Gestores]])
H10: Elvis G Valdez M | I10: =COUNTIF('RequestStats'!D:D,'Metricas 2025'!H10) | J10: =COUNTIFS('RequestStats'!H:H, "A tiempo", 'RequestStats'!D:D,'Metricas 2025'!H10) | K10: =COUNTIFS('RequestStats'!H:H, "Fuera de tiempo", 'RequestStats'!D:D,'Metricas 2025'!H10) | L10: =AVERAGEIFS('RequestStats'!G:G, 'RequestStats'!B:B, ">=" & DATE(2025,1,1), 'RequestStats'!B:B, "<=" & DATE(2025,12,31), 'RequestStats'!D:D, Tabla7151625[[#This Row],[Gestores]])
H11: Julio Adolfo Merino Feliciano | I11: =COUNTIF('RequestStats'!D:D,'Metricas 2025'!H11) | J11: =COUNTIFS('RequestStats'!H:H, "A tiempo", 'RequestStats'!D:D,'Metricas 2025'!H11) | K11: =COUNTIFS('RequestStats'!H:H, "Fuera de tiempo", 'RequestStats'!D:D,'Metricas 2025'!H11) | L11: =AVERAGEIFS('RequestStats'!G:G, 'RequestStats'!B:B, ">=" & DATE(2025,1,1), 'RequestStats'!B:B, "<=" & DATE(2025,12,31), 'RequestStats'!D:D, Tabla7151625[[#This Row],[Gestores]])
H12: Genaro Corporan B | I12: =COUNTIF('RequestStats'!D:D,'Metricas 2025'!H12) | J12: =COUNTIFS('RequestStats'!H:H, "A tiempo", 'RequestStats'!D:D,'Metricas 2025'!H12) | K12: =COUNTIFS('RequestStats'!H:H, "Fuera de tiempo", 'RequestStats'!D:D,'Metricas 2025'!H12) | L12: =AVERAGEIFS('RequestStats'!G:G, 'RequestStats'!B:B, ">=" & DATE(2025,1,1), 'RequestStats'!B:B, "<=" & DATE(2025,12,31), 'RequestStats'!D:D, Tabla7151625[[#This Row],[Gestores]])
H13: Francisco Sanchez V | I13: =COUNTIF('RequestStats'!D:D,'Metricas 2025'!H13) | J13: =COUNTIFS('RequestStats'!H:H, "A tiempo", 'RequestStats'!D:D,'Metricas 2025'!H13) | K13: =COUNTIFS('RequestStats'!H:H, "Fuera de tiempo", 'RequestStats'!D:D,'Metricas 2025'!H13) | L13: =AVERAGEIFS('RequestStats'!G:G, 'RequestStats'!B:B, ">=" & DATE(2025,1,1), 'RequestStats'!B:B, "<=" & DATE(2025,12,31), 'RequestStats'!D:D, Tabla7151625[[#This Row],[Gestores]])
C37: Cuenta de Solicitud | D37: Etiquetas de columna
C38: Etiquetas de fila | D38: Dentro del horario | E38: Fuera de horario | F38: Total general
C39: Copia Digital | D39: 54 | E39: 10 | F39: 64
C40: Prestamo | D40: 5 | E40: 3 | F40: 8
C41: Total general | D41: 59 | E41: 13 | F41: 72
C61: Trimestre 1 - Stats | H61: Trimestre 1 - Stats
C63: Metas del tiempo | F63: PRUDENCIA
C64: A tiempo | D64: Fuera de tiempo | E64: Promedio Tiempo de respuesta | F64: Dentro del horario | G64: Fuera de horario
C65: =COUNTIFS('RequestStats'!H:H, "<=00:59:59", 'RequestStats'!C:C, ">=" & DATE(2025,1,1), 'RequestStats'!C:C, "<=" & DATE(2025,3,31)) | D65: =COUNTIFS('RequestStats'!H:H, ">00:60:00", 'RequestStats'!C:C, ">=" & DATE(2025,1,1), 'RequestStats'!C:C, "<=" & DATE(2025,3,31)) | E65: =AVERAGEIFS('RequestStats'!H:H,'RequestStats'!C:C, "<=" & DATE(2025,3,31), 'RequestStats'!C:C, ">=" & DATE(2025,1,1)) | F65: =COUNTIFS('RequestStats'!C:C, ">=" & DATE(2025,1,1), 'RequestStats'!C:C, "<=" & DATE(2025,3,31), 'RequestStats'!F:F, "Dentro del Horario") | G65: =COUNTIFS('RequestStats'!C:C, ">=" & DATE(2025,1,1), 'RequestStats'!C:C, "<=" & DATE(2025,3,31), 'RequestStats'!F:F, "Fuera de Horario")
C67: Trimestre 1 - Stats | H67: Gestores | I67: Total | J67: A tiempo | K67: Fuera de tiempo | L67: Promedio
C68: Cuenta de Solicitud | D68: Etiquetas de columna | H68: Kevin F Fernandez U | I68: =COUNTIFS('RequestStats'!E:E,Tabla7920[[#This Row],[Gestores]], 'RequestStats'!C:C, ">=" & DATE(2025,1,1), 'RequestStats'!C:C, "<=" & DATE(2025,3,31)) | J68: =COUNTIFS('RequestStats'!I:I, "A tiempo", 'RequestStats'!E:E,'Metricas 2025'!H68, RequestStats!C:C, ">=" & DATE(2025,1,1), RequestStats!C:C, "<=" & DATE(2025,3,31)) | K68: =COUNTIFS('RequestStats'!I:I, "Fuera de tiempo", 'RequestStats'!E:E,'Metricas 2025'!H68, RequestStats!C:C, ">=" & DATE(2025,1,1), RequestStats!C:C, "<=" & DATE(2025,3,31)) | L68: =AVERAGEIFS('RequestStats'!H:H, 'RequestStats'!C:C, ">=" & DATE(2025,1,1), 'RequestStats'!C:C, "<=" & DATE(2025,3,31), 'RequestStats'!E:E, Tabla7920[[#This Row],[Gestores]])
C69: Etiquetas de fila | D69: Dentro del horario | E69: Fuera de horario | F69: Total general | H69: Moises A Laureano M | I69: =COUNTIFS('RequestStats'!E:E,Tabla7920[[#This Row],[Gestores]], 'RequestStats'!C:C, ">=" & DATE(2025,1,1), 'RequestStats'!C:C, "<=" & DATE(2025,3,31)) | J69: =COUNTIFS('RequestStats'!I:I, "A tiempo", 'RequestStats'!E:E,'Metricas 2025'!H69, RequestStats!C:C, ">=" & DATE(2025,1,1), RequestStats!C:C, "<=" & DATE(2025,3,31)) | K69: =COUNTIFS('RequestStats'!I:I, "Fuera de tiempo", 'RequestStats'!E:E,'Metricas 2025'!H69, RequestStats!C:C, ">=" & DATE(2025,1,1), RequestStats!C:C, "<=" & DATE(2025,3,31)) | L69: =AVERAGEIFS('RequestStats'!H:H, 'RequestStats'!C:C, ">=" & DATE(2025,1,1), 'RequestStats'!C:C, "<=" & DATE(2025,3,31), 'RequestStats'!E:E, Tabla7920[[#This Row],[Gestores]])
C70: Copia Digital | D70: =COUNTIFS('RequestStats'!C:C, ">=" & DATE(2025,1,1), 'RequestStats'!C:C, "<=" & DATE(2025,3,31), 'RequestStats'!F:F, "Dentro del Horario", 'RequestStats'!B:B, "Copia Digital" ) | E70: =COUNTIFS('RequestStats'!C:C, ">=" & DATE(2025,1,1), 'RequestStats'!C:C, "<=" & DATE(2025,3,31), 'RequestStats'!F:F, "Fuera de Horario", 'RequestStats'!B:B, "Copia Digital" ) | F70: =SUM(D70:E70) | H70: Andersson Beltre | I70: =COUNTIFS('RequestStats'!E:E,Tabla7920[[#This Row],[Gestores]], 'RequestStats'!C:C, ">=" & DATE(2025,1,1), 'RequestStats'!C:C, "<=" & DATE(2025,3,31)) | J70: =COUNTIFS('RequestStats'!I:I, "A tiempo", 'RequestStats'!E:E,'Metricas 2025'!H70, RequestStats!C:C, ">=" & DATE(2025,1,1), RequestStats!C:C, "<=" & DATE(2025,3,31)) | K70: =COUNTIFS('RequestStats'!I:I, "Fuera de tiempo", 'RequestStats'!E:E,'Metricas 2025'!H70, RequestStats!C:C, ">=" & DATE(2025,1,1), RequestStats!C:C, "<=" & DATE(2025,3,31)) | L70: =AVERAGEIFS('RequestStats'!H:H, 'RequestStats'!C:C, ">=" & DATE(2025,1,1), 'RequestStats'!C:C, "<=" & DATE(2025,3,31), 'RequestStats'!E:E, Tabla7920[[#This Row],[Gestores]])
C71: Prestamo | D71: =COUNTIFS('RequestStats'!C:C, ">=" & DATE(2025,1,1), 'RequestStats'!C:C, "<=" & DATE(2025,3,31), 'RequestStats'!F:F, "Dentro del Horario", 'RequestStats'!B:B, "Prestamo" ) | E71: =COUNTIFS('RequestStats'!C:C, ">=" & DATE(2025,1,1), 'RequestStats'!C:C, "<=" & DATE(2025,3,31), 'RequestStats'!F:F, "Fuera de Horario", 'RequestStats'!B:B, "Prestamo" ) | F71: =SUM(D71:E71) | H71: Julio A Thomas G | I71: =COUNTIFS('RequestStats'!E:E,Tabla7920[[#This Row],[Gestores]], 'RequestStats'!C:C, ">=" & DATE(2025,1,1), 'RequestStats'!C:C, "<=" & DATE(2025,3,31)) | J71: =COUNTIFS('RequestStats'!I:I, "A tiempo", 'RequestStats'!E:E,'Metricas 2025'!H71, RequestStats!C:C, ">=" & DATE(2025,1,1), RequestStats!C:C, "<=" & DATE(2025,3,31)) | K71: =COUNTIFS('RequestStats'!I:I, "Fuera de tiempo", 'RequestStats'!E:E,'Metricas 2025'!H71, RequestStats!C:C, ">=" & DATE(2025,1,1), RequestStats!C:C, "<=" & DATE(2025,3,31)) | L71: =AVERAGEIFS('RequestStats'!H:H, 'RequestStats'!C:C, ">=" & DATE(2025,1,1), 'RequestStats'!C:C, "<=" & DATE(2025,3,31), 'RequestStats'!E:E, Tabla7920[[#This Row],[Gestores]])
C72: Total general | D72: =SUM(D70:D71) | E72: =SUM(E70:E71) | F72: =SUM(F70:F71)
C85: Trimestre 2 - Stats | H85: Trimestre 2 - Stats
C87: Metas del tiempo | F87: PRUDENCIA
C88: A tiempo | D88: Fuera de tiempo | E88: Promedio Tiempo de respuesta | F88: Dentro del horario | G88: Fuera de horario
C89: =COUNTIFS('RequestStats'!H:H, "<=00:59:59", 'RequestStats'!C:C, ">=" & DATE(2025,4,1), 'RequestStats'!C:C, "<=" & DATE(2025,6,31)) | D89: =COUNTIFS('RequestStats'!H:H, ">=00:60:00", 'RequestStats'!C:C, ">=" & DATE(2025,4,1), 'RequestStats'!C:C, "<=" & DATE(2025,6,31)) | E89: =AVERAGEIFS('RequestStats'!H:H, 'RequestStats'!C:C, ">=" & DATE(2025,4,1), 'RequestStats'!C:C, "<=" & DATE(2025,6,31)) | F89: =COUNTIFS('RequestStats'!C:C, ">=" & DATE(2025,4,1), 'RequestStats'!C:C, "<=" & DATE(2025,6,31), 'RequestStats'!F:F, "Dentro del Horario") | G89: =COUNTIFS('RequestStats'!C:C, ">=" & DATE(2025,4,1), 'RequestStats'!C:C, "<=" & DATE(2025,6,31), 'RequestStats'!F:F, "Fuera de Horario")
C91: Trimestre 2 - Stats | H91: Gestores | I91: Total | J91: A tiempo | K91: Fuera de tiempo | L91: Promedio
C92: Cuenta de Solicitud | D92: Etiquetas de columna | H92: Kevin F Fernandez U | I92: =COUNTIFS('RequestStats'!E:E,Tabla711121122[[#This Row],[Gestores]], 'RequestStats'!C:C, ">=" & DATE(2025,4,1), 'RequestStats'!C:C, "<=" & DATE(2025,6,31)) | J92: =COUNTIFS('RequestStats'!I:I, "A tiempo", 'RequestStats'!E:E,Tabla711121122[[#This Row],[Gestores]], 'RequestStats'!C:C, ">=" & DATE(2025,4,1), 'RequestStats'!C:C, "<=" & DATE(2025,6,31)) | K92: =COUNTIFS('RequestStats'!I:I, "Fuera de tiempo", 'RequestStats'!E:E,Tabla711121122[[#This Row],[Gestores]], 'RequestStats'!C:C, ">=" & DATE(2025,4,1), 'RequestStats'!C:C, "<=" & DATE(2025,6,31)) | L92: =AVERAGEIFS('RequestStats'!H:H, 'RequestStats'!C:C, ">=" & DATE(2025,4,1), 'RequestStats'!C:C, "<=" & DATE(2025,6,31), 'RequestStats'!E:E, Tabla711121122[[#This Row],[Gestores]])
C93: Etiquetas de fila | D93: Dentro del horario | E93: Fuera de horario | F93: Total general | H93: Moises A Laureano M | I93: =COUNTIFS('RequestStats'!E:E,Tabla711121122[[#This Row],[Gestores]], 'RequestStats'!C:C, ">=" & DATE(2025,4,1), 'RequestStats'!C:C, "<=" & DATE(2025,6,31)) | J93: =COUNTIFS('RequestStats'!I:I, "A tiempo", 'RequestStats'!E:E,Tabla711121122[[#This Row],[Gestores]], 'RequestStats'!C:C, ">=" & DATE(2025,4,1), 'RequestStats'!C:C, "<=" & DATE(2025,6,31)) | K93: =COUNTIFS('RequestStats'!I:I, "Fuera de tiempo", 'RequestStats'!E:E,Tabla711121122[[#This Row],[Gestores]], 'RequestStats'!C:C, ">=" & DATE(2025,4,1), 'RequestStats'!C:C, "<=" & DATE(2025,6,31)) | L93: =AVERAGEIFS('RequestStats'!H:H, 'RequestStats'!C:C, ">=" & DATE(2025,4,1), 'RequestStats'!C:C, "<=" & DATE(2025,6,31), 'RequestStats'!E:E, Tabla711121122[[#This Row],[Gestores]])
C94: Copia Digital | D94: =COUNTIFS('RequestStats'!C:C, ">=" & DATE(2025,4,1), 'RequestStats'!C:C, "<=" & DATE(2025,6,31), 'RequestStats'!F:F, "Dentro del Horario", 'RequestStats'!B:B, "Copia Digital" ) | E94: =COUNTIFS('RequestStats'!C:C, ">=" & DATE(2025,4,1), 'RequestStats'!C:C, "<=" & DATE(2025,6,31), 'RequestStats'!F:F, "Fuera de Horario", 'RequestStats'!B:B, "Copia Digital" ) | F94: =SUM(D94:E94) | H94: Andersson Beltre | I94: =COUNTIFS('RequestStats'!E:E,Tabla711121122[[#This Row],[Gestores]], 'RequestStats'!C:C, ">=" & DATE(2025,4,1), 'RequestStats'!C:C, "<=" & DATE(2025,6,31)) | J94: =COUNTIFS('RequestStats'!I:I, "A tiempo", 'RequestStats'!E:E,Tabla711121122[[#This Row],[Gestores]], 'RequestStats'!C:C, ">=" & DATE(2025,4,1), 'RequestStats'!C:C, "<=" & DATE(2025,6,31)) | K94: =COUNTIFS('RequestStats'!I:I, "Fuera de tiempo", 'RequestStats'!E:E,Tabla711121122[[#This Row],[Gestores]], 'RequestStats'!C:C, ">=" & DATE(2025,4,1), 'RequestStats'!C:C, "<=" & DATE(2025,6,31)) | L94: =AVERAGEIFS('RequestStats'!H:H, 'RequestStats'!C:C, ">=" & DATE(2025,4,1), 'RequestStats'!C:C, "<=" & DATE(2025,6,31), 'RequestStats'!E:E, Tabla711121122[[#This Row],[Gestores]])
C95: Prestamo | D95: =COUNTIFS('RequestStats'!C:C, ">=" & DATE(2025,4,1), 'RequestStats'!C:C, "<=" & DATE(2025,6,31), 'RequestStats'!F:F, "Dentro del Horario", 'RequestStats'!B:B, "Prestamo" ) | E95: =COUNTIFS('RequestStats'!C:C, ">=" & DATE(2025,4,1), 'RequestStats'!C:C, "<=" & DATE(2025,6,31), 'RequestStats'!F:F, "Fuera de Horario", 'RequestStats'!B:B, "Prestamo" ) | F95: =SUM(D95:E95) | H95: Julio A Thomas G | I95: =COUNTIFS('RequestStats'!E:E,Tabla711121122[[#This Row],[Gestores]], 'RequestStats'!C:C, ">=" & DATE(2025,4,1), 'RequestStats'!C:C, "<=" & DATE(2025,6,31)) | J95: =COUNTIFS('RequestStats'!I:I, "A tiempo", 'RequestStats'!E:E,Tabla711121122[[#This Row],[Gestores]], 'RequestStats'!C:C, ">=" & DATE(2025,4,1), 'RequestStats'!C:C, "<=" & DATE(2025,6,31)) | K95: =COUNTIFS('RequestStats'!I:I, "Fuera de tiempo", 'RequestStats'!E:E,Tabla711121122[[#This Row],[Gestores]], 'RequestStats'!C:C, ">=" & DATE(2025,4,1), 'RequestStats'!C:C, "<=" & DATE(2025,6,31)) | L95: =AVERAGEIFS('RequestStats'!H:H, 'RequestStats'!C:C, ">=" & DATE(2025,4,1), 'RequestStats'!C:C, "<=" & DATE(2025,6,31), 'RequestStats'!E:E, Tabla711121122[[#This Row],[Gestores]])
C96: Total general | D96: =SUM(D94:D95) | E96: =SUM(E94:E95) | F96: =SUM(F94:F95) | H96: Elvis G Valdez M | I96: =COUNTIFS('RequestStats'!E:E,Tabla711121122[[#This Row],[Gestores]], 'RequestStats'!C:C, ">=" & DATE(2025,4,1), 'RequestStats'!C:C, "<=" & DATE(2025,6,31)) | J96: =COUNTIFS('RequestStats'!I:I, "A tiempo", 'RequestStats'!E:E,Tabla711121122[[#This Row],[Gestores]], 'RequestStats'!C:C, ">=" & DATE(2025,4,1), 'RequestStats'!C:C, "<=" & DATE(2025,6,31)) | K96: =COUNTIFS('RequestStats'!I:I, "Fuera de tiempo", 'RequestStats'!E:E,Tabla711121122[[#This Row],[Gestores]], 'RequestStats'!C:C, ">=" & DATE(2025,4,1), 'RequestStats'!C:C, "<=" & DATE(2025,6,31)) | L96: =AVERAGEIFS('RequestStats'!H:H, 'RequestStats'!C:C, ">=" & DATE(2025,4,1), 'RequestStats'!C:C, "<=" & DATE(2025,6,31), 'RequestStats'!E:E, Tabla711121122[[#This Row],[Gestores]])
H97: Julio Adolfo Merino Feliciano | I97: =COUNTIFS('RequestStats'!E:E,Tabla711121122[[#This Row],[Gestores]], 'RequestStats'!C:C, ">=" & DATE(2025,4,1), 'RequestStats'!C:C, "<=" & DATE(2025,6,31)) | J97: =COUNTIFS('RequestStats'!I:I, "A tiempo", 'RequestStats'!E:E,Tabla711121122[[#This Row],[Gestores]], 'RequestStats'!C:C, ">=" & DATE(2025,4,1), 'RequestStats'!C:C, "<=" & DATE(2025,6,31)) | K97: =COUNTIFS('RequestStats'!I:I, "Fuera de tiempo", 'RequestStats'!E:E,Tabla711121122[[#This Row],[Gestores]], 'RequestStats'!C:C, ">=" & DATE(2025,4,1), 'RequestStats'!C:C, "<=" & DATE(2025,6,31)) | L97: =AVERAGEIFS('RequestStats'!H:H, 'RequestStats'!C:C, ">=" & DATE(2025,4,1), 'RequestStats'!C:C, "<=" & DATE(2025,6,31), 'RequestStats'!E:E, Tabla711121122[[#This Row],[Gestores]])
C111: Trimestre 3 - Stats | H111: Trimestre 3 - Stats
C113: Metas del tiempo | F113: PRUDENCIA
...

Sheet RequestStats 2025
A1: ID | B1: Solicitud | C1: Creación | D1: Respuesta | E1: Gestor | F1: Prudencia | G1: ValidaciónCreación | H1: TiempoLaboralEfectivo | I1: Calificación | J1: Trimestre
