Workbook
Name ADMS: [1]Parametros!$E$4:$E$36
Name nomes: [1]Parametros!$B$4:$C$15

Sheet Base de Datos
C1: MATRIZ CONTROL DE DOCUMENTOS Y EXPEDIENTES - LA FERIA
A4: PROCEDENCIA DEL DOCUMENTO O EXPEDIENTE | C4: UBICACIÓN DEL DOCUMENTO O EXPEDIENTE EN EL ARCHIVO | G4: INFORMACIÓN DEL CONTRIBUYENTE | J4: INFORMACIÓN SOBRE EL DOCUMENTO O EXPEDIENTE | M4: ESTADO Y CONDICIÓN DEL DOCUMENTO O EXPEDIENTE
A5: FECHA RECEPCIÓN (EN EL ARCHIVO) | B5: AREA | C5: CAJA # | D5: ANAQUEL | E5: NIVEL DEL ANAQUEL | F5: POSICIÓN | G5: TIPO CONTRIBUYENTE | H5: CEDULA - RNC | I5: NOMBRE | J5: Descripción del Documento | K5: FECHA | L5: ASUNTO - TRAMITE | M5: STATUS | N5: FECHA DE PRESTAMO | O5: Solicitante | P5: OBSERVACIÓN
M15240: 24-23-0000262

Sheet Lista Desprendible
M3: Contribuyente
C4: ADMINISTRACIÓN LOCAL AZUA | F4: Solicitud de compensación de impuestos a los activos con saldo a favor de ISR. | I4: Transferido a Archivo Central | M4: Persona Física
C5: ADMINISTRACIÓN LOCAL BANÍ | F5: Solicitud de autorización de reembolso o compensación del saldo a favor de asalariados (IR-13). | I5: Eliminado | M5: Persona Jurídica
C6: ADMINISTRACIÓN LOCAL BARAHONA | F6: Solicitud de reembolso del saldo a favor de Personas Físicas y asalariados acogidos a la Ley 179-09. | I6: Prestado | M6: Sucesoral
C7: ADMINISTRACIÓN LOCAL BÁVARO | F7: Solicitud de compensación de retenciones del Estado. | I7: Archivo de Gestion | M7: Organización sin fines de lucro
C8: ADMINISTRACIÓN LOCAL BOCA CHICA | F8: Solicitud de exención de Anticipos. | I8: Digitalizado y Eliminado
C9: ADMINISTRACIÓN LOCAL BONAO | F9: Solicitud de Recurso de Reconsideración. | I9: Digitalizado y en Archivo de Gestión
C10: ADMINISTRACIÓN LOCAL EL SEIBO | F10: Escrito de Descargo. | I10: Digitalizado y en Archivo Central
C11: ADMINISTRACIÓN LOCAL HERRERA | F11: Solicitud de prórroga de Escrito de Descargo.
C12: ADMINISTRACIÓN LOCAL HIGÜEY | F12: Solicitud de reembolso de ITBIS.
C13: ADMINISTRACIÓN LOCAL LA FERIA | F13: Solicitud de compensación de Anticipos con saldo a favor en renta y activos.
C14: ADMINISTRACIÓN LOCAL LA ROMANA | F14: Solicitud de exención de Activos (por leyes especiales CONFOTUR)
C15: ADMINISTRACIÓN LOCAL LA VEGA | F15: Solicitud de Estimación
C16: ADMINISTRACIÓN LOCAL LINCOLN | F16: Solicitud de autorización de rectificativas del Formato 606 de cualquier periodo y de los demás Formatos de envío de periodos posteriores a enero 2015 (exceptuando el 623).
C17: ADMINISTRACIÓN LOCAL LOS MINA | F17: Solicitud de presentación de Declaraciones Juradas (exceptuando IR-3 y Dior).
C18: ADMINISTRACIÓN LOCAL LOS PRÓCERES | F18: Solicitud de aplicación de crédito por retenciones de intereses bancarios (Norma 13-11).
C19: ADMINISTRACIÓN LOCAL MÁXIMO GÓMEZ | F19: Crédito PST (anteriores al período fiscal 2016).
C20: ADMINISTRACIÓN LOCAL MOCA | F20: Solicitud de Reintegro de Cheques.
C21: ADMINISTRACIÓN LOCAL MONTECRISTI | F21: Solicitud de Reintegro de Cheques para entidades del Estado.
C22: ADMINISTRACIÓN LOCAL NAGUA | F22: Solicitud de rescisión de venta inmobiliaria.
... C96: GERENCIA DE GRANDES CONTRIBUYENTES - Depto. Precio de Transferencia | F96: Solicitud de copia de Declaración Jurada.
F97: Solicitud de autorización de rectificativas del Formato 606.
F98: Solicitud de reducción de recargos (descuento por pronto pago, Art. 252 del Código Tributario).
F99: Solicitud de Cese Temporal de operaciones para Personas Jurídicas.
F100: Solicitud de levantamiento del Cese Temporal de operaciones para Personas Jurídicas.
F101: Solicitud de disminución o eliminación de multas.
F102: Solicitud para sustituir o cancelar el acceso a la bitácora electrónica y el libro de ventas.
C103: GERENCIA DE RECURSOS HUMANOS - Coordinadores Regionales RRHH | F103: Solicitud de cambio de garantía en Acuerdo de Pago.
C104: GERENCIA DE RECURSOS HUMANOS - Depto. Desarrollo y Carrera | F104: Solicitud de prórroga para el envío de los Formatos 606, 607 y 608.
C105: GERENCIA DE RECURSOS HUMANOS - Depto. Prevención Riesgo Ocupacional | F105: Solicitud de prescripción de deudas (OM, MO).
C106: GERENCIA DE RECURSOS HUMANOS - Depto. Operaciones de Recursos Humanos | F106: Solicitud de Modificaciones al RNC de Personas Físicas.
C107: GERENCIA DE RECURSOS HUMANOS - Sección Desarrollo Organizacional | F107: Solicitud de Acuerdo de Pago.
C108: GERENCIA DE RECURSOS HUMANOS - Sección Gestión de la Formación | F108: Solicitud de inactivación de obligaciones marcadas o enviadas por error en periodos anteriores.
C109: GERENCIA DE RECURSOS HUMANOS - Sección Reclutamiento y Selección | F109: Solicitud de inactivación de obligaciones a Personas Físicas que han dejado de operar.
C110: GERENCIA DE RECURSOS HUMANOS - Sección Registro y Control | F110: Solicitud de prórroga para la presentación de la Declaración IR-2.
C111: GERENCIA DE RECURSOS HUMANOS - Sección Salud Laboral | F111: Solicitud de Certificación de partición amigable entre esposos.
C112: GERENCIA DE EXPERIENCIA DEL CONTRIBUYENTE Y CIUDADANO - Departamento de Experiencia y Aseguramiento de la Calidad | F112: Solicitud de Certificación de IPI.
C113: GERENCIA DE EXPERIENCIA DEL CONTRIBUYENTE Y CIUDADANO - Departamento de Canales de Asistencia y OFV | F113: Solicitud de Certificación de IPI para Entidades Gubernamentales.
C114: GERENCIA DE RIESGOS TRIBUTARIOS-Departamento de Riesgo Global Tributario | F114: Solicitud de Reactivación de RNC de Compañías.
... C125: SEDE CENTRAL | F125: Solicitud de Consultas Técnicas.
...

Sheet ListaSeleccion
B1: Área | C1: Tipo de Documento (Asunto / Tramite) | E1: Estatus
B2: ADMINISTRACIÓN LOCAL AZUA | C2: Solicitud de compensación de impuestos a los activos con saldo a favor de ISR. | E2: En Archivo Central
B3: ADMINISTRACIÓN LOCAL BANÍ | C3: Solicitud de autorización de reembolso o compensación del saldo a favor de asalariados (IR-13). | E3: Prestado
B4: ADMINISTRACIÓN LOCAL BARAHONA | C4: Solicitud de reembolso del saldo a favor de Personas Físicas y asalariados acogidos a la Ley 179-09.
B5: ADMINISTRACIÓN LOCAL BÁVARO | C5: Solicitud de compensación de retenciones del Estado.
B6: ADMINISTRACIÓN LOCAL BOCA CHICA | C6: Solicitud de exención de Anticipos.
B7: ADMINISTRACIÓN LOCAL BONAO | C7: Solicitud de Recurso de Reconsideración.
B8: ADMINISTRACIÓN LOCAL EL SEIBO | C8: Escrito de Descargo.
B9: ADMINISTRACIÓN LOCAL HERRERA | C9: Solicitud de prórroga de Escrito de Descargo.
B10: ADMINISTRACIÓN LOCAL HIGÜEY | C10: Solicitud de reembolso de ITBIS.
B11: ADMINISTRACIÓN LOCAL LA FERIA | C11: Solicitud de compensación de Anticipos con saldo a favor en renta y activos.
B12: ADMINISTRACIÓN LOCAL LA ROMANA | C12: Solicitud de exención de Activos (por leyes especiales CONFOTUR)
B13: ADMINISTRACIÓN LOCAL LA VEGA | C13: Solicitud de Estimación
B14: ADMINISTRACIÓN LOCAL LINCOLN | C14: Solicitud de autorización de rectificativas del Formato 606 de cualquier periodo y de los demás Formatos de envío de periodos posteriores a enero 2015 (exceptuando el 623).
B15: ADMINISTRACIÓN LOCAL LOS MINA | C15: Solicitud de presentación de Declaraciones Juradas (exceptuando IR-3 y Dior).
... B113: SEDE CENTRAL | C113: Solicitud aprobación informes de consultores y docentes.
C114: Solicitud de elaboración de contratos
C115: Remisión de contratos.
C116: Solicitud aprobación de participación.
C117: Carta aval de participación.
C118: Solicitud pago de viáticos.
C119: Solicitud pago de servicios (hotel, boletos aéreos, seguros de viaje, equipaje).
C120: Solicitud intercambio de información (externas).
C121: Solicitud intercambio de información (internas).
C122: Solicitud de reembolsos.
C123: Solicitud de Consultas Técnicas.
C124: Solicitud de Cooperación.
C125: Convocatorias (monografías, becas de investigación, cursos).
... C508: Recibo de Pago del uno (1%) por Ciento de Plan de Construcciones.

Sheet Datos #
B3: Metricas
B4: Satus | D4: =COUNTA('Base de Datos'!M6:M15230) -> 15225 | F4: Area | H4: =COUNTA('Base de Datos'!B6:B15230) -> 15225 | J4: Asunto / tramite | L4: =COUNTA('Base de Datos'!L6:L15230) -> 15224 | O4: Contribuyente
B5: Satus | C5: Transferido a Archivo Central | D5: =COUNTIF('Base de Datos'!M6:M15230,'Datos #'!C5) -> 2 | F5: Area | G5: ADMINISTRACIÓN LOCAL AZUA | H5: =COUNTIF('Base de Datos'!B$6:B$15230,G5) -> 0 | J5: Asunto / tramite | K5: Solicitud de compensación de impuestos a los activos con saldo a favor de ISR. | L5: =COUNTIF('Base de Datos'!L$6:L$15230,K5) -> 0 | O5: Persona Física
C6: Eliminado | D6: =COUNTIF('Base de Datos'!M6:M15230,'Datos #'!C6) -> 0 | G6: ADMINISTRACIÓN LOCAL BANÍ | H6: =COUNTIF('Base de Datos'!B$6:B$15230,G6) -> 0 | K6: Solicitud de autorización de reembolso o compensación del saldo a favor de asalariados (IR-13). | L6: =COUNTIF('Base de Datos'!L$6:L$15230,K6) -> 0 | O6: Persona Jurídica
C7: Prestado | D7: =COUNTIF('Base de Datos'!M5:M15230,'Datos #'!C7) -> 2 | G7: ADMINISTRACIÓN LOCAL BARAHONA | H7: =COUNTIF('Base de Datos'!B$6:B$15230,G7) -> 0 | K7: Solicitud de reembolso del saldo a favor de Personas Físicas y asalariados acogidos a la Ley 179-09. | L7: =COUNTIF('Base de Datos'!L$6:L$15230,K7) -> 0 | O7: Sucesoral
C8: Digitalizado y eliminado | D8: =COUNTIF('Base de Datos'!M6:M15230,'Datos #'!C8) -> 0 | G8: ADMINISTRACIÓN LOCAL BÁVARO | H8: =COUNTIF('Base de Datos'!B$6:B$15230,G8) -> 0 | K8: Solicitud de compensación de retenciones del Estado. | L8: =COUNTIF('Base de Datos'!L$6:L$15230,K8) -> 0 | O8: Organización sin fines de lucro
C9: Digitalizado y en Archivo de Gestión | D9: =COUNTIF('Base de Datos'!M8:M15233,'Datos #'!C9) -> 2182 | G9: ADMINISTRACIÓN LOCAL BOCA CHICA | H9: =COUNTIF('Base de Datos'!B$6:B$15230,G9) -> 0 | K9: Solicitud de exención de Anticipos. | L9: =COUNTIF('Base de Datos'!L$6:L$15230,K9) -> 0
C10: Digitalizado y en Archivo Central | D10: =COUNTIF('Base de Datos'!M7:M15233,'Datos #'!C10) -> 0 | G10: ADMINISTRACIÓN LOCAL BONAO | H10: =COUNTIF('Base de Datos'!B$6:B$15230,G10) -> 0 | K10: Solicitud de Recurso de Reconsideración. | L10: =COUNTIF('Base de Datos'!L$6:L$15230,K10) -> 0
C11: Archivo de Gestion | D11: =COUNTIF('Base de Datos'!M8:M15233,'Datos #'!C11) -> 13038 | G11: ADMINISTRACIÓN LOCAL EL SEIBO | H11: =COUNTIF('Base de Datos'!B$6:B$15230,G11) -> 0 | K11: Escrito de Descargo. | L11: =COUNTIF('Base de Datos'!L$6:L$15230,K11) -> 0
G12: ADMINISTRACIÓN LOCAL HERRERA | H12: =COUNTIF('Base de Datos'!B$6:B$15230,G12) -> 0 | K12: Solicitud de prórroga de Escrito de Descargo. | L12: =COUNTIF('Base de Datos'!L$6:L$15230,K12) -> 0
G13: ADMINISTRACIÓN LOCAL HIGÜEY | H13: =COUNTIF('Base de Datos'!B$6:B$15230,G13) -> 0 | K13: Solicitud de reembolso de ITBIS. | L13: =COUNTIF('Base de Datos'!L$6:L$15230,K13) -> 0
G14: ADMINISTRACIÓN LOCAL LA FERIA | H14: =COUNTIF('Base de Datos'!B$6:B$15230,G14) -> 15225 | K14: Solicitud de compensación de Anticipos con saldo a favor en renta y activos. | L14: =COUNTIF('Base de Datos'!L$6:L$15230,K14) -> 0
G15: ADMINISTRACIÓN LOCAL LA ROMANA | H15: =COUNTIF('Base de Datos'!B$6:B$15230,G15) -> 0 | K15: Solicitud de exención de Activos (por leyes especiales CONFOTUR) | L15: =COUNTIF('Base de Datos'!L$6:L$15230,K15) -> 0
G16: ADMINISTRACIÓN LOCAL LA VEGA | H16: =COUNTIF('Base de Datos'!B$6:B$15230,G16) -> 0 | K16: Solicitud de Estimación | L16: =COUNTIF('Base de Datos'!L$6:L$15230,K16) -> 0
G17: ADMINISTRACIÓN LOCAL LINCOLN | H17: =COUNTIF('Base de Datos'!B$6:B$15230,G17) -> 0 | K17: Solicitud de autorización de rectificativas del Formato 606 de cualquier periodo y de los demás Formatos de envío de periodos posteriores a enero 2015 (exceptuando el 623). | L17: =COUNTIF('Base de Datos'!L$6:L$15230,K17) -> 0
G18: ADMINISTRACIÓN LOCAL LOS MINA | H18: =COUNTIF('Base de Datos'!B$6:B$15230,G18) -> 0 | K18: Solicitud de presentación de Declaraciones Juradas (exceptuando IR-3 y Dior). | L18: =COUNTIF('Base de Datos'!L$6:L$15230,K18) -> 0
G19: ADMINISTRACIÓN LOCAL LOS PRÓCERES | H19: =COUNTIF('Base de Datos'!B$6:B$15230,G19) -> 0 | K19: Solicitud de aplicación de crédito por retenciones de intereses bancarios (Norma 13-11). | L19: =COUNTIF('Base de Datos'!L$6:L$15230,K19) -> 0
G20: ADMINISTRACIÓN LOCAL MÁXIMO GÓMEZ | H20: =COUNTIF('Base de Datos'!B$6:B$15230,G20) -> 0 | K20: Crédito PST (anteriores al período fiscal 2016). | L20: =COUNTIF('Base de Datos'!L$6:L$15230,K20) -> 0
G21: ADMINISTRACIÓN LOCAL MOCA | H21: =COUNTIF('Base de Datos'!B$6:B$15230,G21) -> 0 | K21: Solicitud de Reintegro de Cheques. | L21: =COUNTIF('Base de Datos'!L$6:L$15230,K21) -> 0
G22: ADMINISTRACIÓN LOCAL MONTECRISTI | H22: =COUNTIF('Base de Datos'!B$6:B$15230,G22) -> 0 | K22: Solicitud de Reintegro de Cheques para entidades del Estado. | L22: =COUNTIF('Base de Datos'!L$6:L$15230,K22) -> 0
G23: ADMINISTRACIÓN LOCAL NAGUA | H23: =COUNTIF('Base de Datos'!B$6:B$15230,G23) -> 0 | K23: Solicitud de rescisión de venta inmobiliaria. | L23: =COUNTIF('Base de Datos'!L$6:L$15230,K23) -> 0
... G67: ESTAFETA LA FERIA | H67: =COUNTIF('Base de Datos'!B$6:B$15230,G67) -> 0 | K67: Gestión de expedientes que inician proceso de cobro procedentes de recursos de reconsideración. | L67: =COUNTIF('Base de Datos'!L$6:L$15230,K67) -> 0
C68: Cantidad de Documentos | D68: =SUM(D71:D50003) -> 15225 | G68: ESTAFETA PUERTO CAUCEDO BOCA CHICA | H68: =COUNTIF('Base de Datos'!B$6:B$15230,G68) -> 0 | K68: Solicitud de acuerdo de pago en Fiscalización o RR. | L68: =COUNTIF('Base de Datos'!L$6:L$15230,K68) -> 0
C69: Cantidad de cajas | D69: =COUNTA(C71:C99999) -> 133 | G69: ESTAFETA PUERTO DE HAINA SAN CRISTÓBAL | H69: =COUNTIF('Base de Datos'!B$6:B$15230,G69) -> 0 | K69: Solicitudes de renegociación de acuerdos de pago - cambios de garantías. | L69: =COUNTIF('Base de Datos'!L$6:L$15230,K69) -> 0
C70: No. Caja | D70: Cant./Caja | G70: ESTAFETA PUERTO PLATA | H70: =COUNTIF('Base de Datos'!B$6:B$15230,G70) -> 0 | K70: Notificación - Requerimiento de Reconsideración/ Fiscalización | L70: =COUNTIF('Base de Datos'!L$6:L$15230,K70) -> 0
C71: {=_xlfn._xlws.SORT(_xlfn.UNIQUE(_xlfn._xlws.FILTER('Base de Datos'!C6:C15232, IFERROR('Base de Datos'!C6:C15232<>"", FALSE))))} -> Declaración de Impuesto sobre la Renta (IR-2). GAVETA 01 | D71: =COUNTIF('Base de Datos'!C$6:C$15230,C71) -> 59 | G71: ESTAFETA PUERTO SANSOUCI ZONA ORIENTAL | H71: =COUNTIF('Base de Datos'!B$6:B$15230,G71) -> 0 | K71: Notificación - Requerimiento acuerdo de pago de cobro persuasivo. | L71: =COUNTIF('Base de Datos'!L$6:L$15230,K71) -> 0
C72: Declaración de Impuesto sobre la Renta (IR-2). GAVETA 02 | D72: =COUNTIF('Base de Datos'!C$6:C$15230,C72) -> 68 | G72: ESTAFETA PUERTO SANTO DOMINGO SAN CARLOS | H72: =COUNTIF('Base de Datos'!B$6:B$15230,G72) -> 0 | K72: Notificación - Requerimiento Acuerdo de pago de Cobro Coactivo. | L72: =COUNTIF('Base de Datos'!L$6:L$15230,K72) -> 0
C73: Declaración de Impuesto sobre la Renta (IR-2). GAVETA 03 | D73: =COUNTIF('Base de Datos'!C$6:C$15230,C73) -> 64 | G73: GCIA. ADMINISTRATIVA Y FINANCIERA – Depto. Administración de Inventarios | H73: =COUNTIF('Base de Datos'!B$6:B$15230,G73) -> 0 | K73: Solicitud de Reembolso por Pagos en Exceso o Indebidos. | L73: =COUNTIF('Base de Datos'!L$6:L$15230,K73) -> 0
C74: Declaración de Impuesto sobre la Renta (IR-2). GAVETA 04 | D74: =COUNTIF('Base de Datos'!C$6:C$15230,C74) -> 75 | G74: GCIA. ADMINISTRATIVA Y FINANCIERA – Depto. Compras | H74: =COUNTIF('Base de Datos'!B$6:B$15230,G74) -> 0 | K74: Solicitud de Reembolso por Transferencias Inmobiliarias no Realizadas (Transferencias, Hipotecas, entre otras). | L74: =COUNTIF('Base de Datos'!L$6:L$15230,K74) -> 0
C75: Declaración de Impuesto sobre la Renta (IR-2). GAVETA 05 | D75: =COUNTIF('Base de Datos'!C$6:C$15230,C75) -> 157 | G75: GCIA. ADMINISTRATIVA Y FINANCIERA – Depto. Contabilidad | H75: =COUNTIF('Base de Datos'!B$6:B$15230,G75) -> 0 | K75: Solicitud de Reembolso por Depósito en Consignación. | L75: =COUNTIF('Base de Datos'!L$6:L$15230,K75) -> 0
C76: Declaración de Impuesto sobre la Renta (IR-2). GAVETA 07 | D76: =COUNTIF('Base de Datos'!C$6:C$15230,C76) -> 64 | G76: GCIA. ADMINISTRATIVA Y FINANCIERA – Depto. Tesorería | H76: =COUNTIF('Base de Datos'!B$6:B$15230,G76) -> 0 | K76: Solicitud rectificativa pliego de modificaciones. | L76: =COUNTIF('Base de Datos'!L$6:L$15230,K76) -> 0
C77: Declaración de Impuesto sobre la Renta (IR-2). GAVETA 08 | D77: =COUNTIF('Base de Datos'!C$6:C$15230,C77) -> 79 | G77: GCIA. APOYO LOGISTICO - Depto. De Ingeniería | H77: =COUNTIF('Base de Datos'!B$6:B$15230,G77) -> 0 | K77: Certificación de Exención de Impuesto Selectivo a los Servicios de Seguros del Sector Agropecuario (Ley 182-09). | L77: =COUNTIF('Base de Datos'!L$6:L$15230,K77) -> 0
C78: Declaración de Impuesto sobre la Renta (IR-2). GAVETA 09 | D78: =COUNTIF('Base de Datos'!C$6:C$15230,C78) -> 80 | G78: GCIA. APOYO LOGISTICO - Transportación | H78: =COUNTIF('Base de Datos'!B$6:B$15230,G78) -> 0 | K78: Solicitud de Traspaso de Soluciones Fiscales de un contribuyente a otro. | L78: =COUNTIF('Base de Datos'!L$6:L$15230,K78) -> 0
C79: PERSONA FISICA GAVETA 6 | D79: =COUNTIF('Base de Datos'!C$6:C$15230,C79) -> 77 | G79: GCIA. COBRANZA – COBRO COACTIVO | H79: =COUNTIF('Base de Datos'!B$6:B$15230,G79) -> 0 | K79: Declaración Jurada de Sucesiones. | L79: =COUNTIF('Base de Datos'!L$6:L$15230,K79) -> 0
C80: SECCON PERSONA FISICA GAVETA 11 | D80: =COUNTIF('Base de Datos'!C$6:C$15230,C80) -> 1 | G80: GCIA. COBRANZA – COBRO PERSUASIVO | H80: =COUNTIF('Base de Datos'!B$6:B$15230,G80) -> 0 | K80: Solicitud de Certificaciones de Sucesiones | L80: =COUNTIF('Base de Datos'!L$6:L$15230,K80) -> 0
C81: SECCON PERSONA FISICAS CAJA 232 | D81: =COUNTIF('Base de Datos'!C$6:C$15230,C81) -> 2 | G81: GCIA. FISCALIZACION EXTERNA GRANDES CONTRIBUYENTES | H81: =COUNTIF('Base de Datos'!B$6:B$15230,G81) -> 0 | K81: Solicitud de Certificación de Estados Financieros Auditados. | L81: =COUNTIF('Base de Datos'!L$6:L$15230,K81) -> 0
C82: SECCON PERSONA FISICAS GAVETA 09 | D82: =COUNTIF('Base de Datos'!C$6:C$15230,C82) -> 1 | G82: GCIA. FISCALIZACION EXTERNA MEDIANOS CONTRIBUYENTES | H82: =COUNTIF('Base de Datos'!B$6:B$15230,G82) -> 0 | K82: Solicitud de Certificación de cumplimiento de obligaciones fiscales (al día en la declaración y/o Pago de Impuestos). | L82: =COUNTIF('Base de Datos'!L$6:L$15230,K82) -> 0
C83: SECCON PERSONA FISICAS GAVETA 10 | D83: =COUNTIF('Base de Datos'!C$6:C$15230,C83) -> 3 | G83: GCIA. II FISCALIZACION EXTERNA DE MEDIANOS CONTRIBUYENTES | H83: =COUNTIF('Base de Datos'!B$6:B$15230,G83) -> 0 | K83: Solicitud de corrección de pagos. | L83: =COUNTIF('Base de Datos'!L$6:L$15230,K83) -> 0
... C116: SECCON PERSONA JURIDICA GAVETA 31 | D116: =COUNTIF('Base de Datos'!C$6:C$15230,C116) -> 70 | G116: SEDE CENTRAL | H116: =COUNTIF('Base de Datos'!B$6:B$15230,G116) -> 0 | K116: Solicitud aprobación informes de consultores y docentes. | L116: =COUNTIF('Base de Datos'!L$6:L$15230,K116) -> 0
C117: SECCON PERSONA JURIDICA GAVETA 32 | D117: =COUNTIF('Base de Datos'!C$6:C$15230,C117) -> 82 | K117: Solicitud de elaboración de contratos | L117: =COUNTIF('Base de Datos'!L$6:L$15230,K117) -> 0
...
